Traceback (most recent call last):
  File "/Users/pytka/opt/anaconda3/lib/python3.8/site-packages/jupyter_cache/executors/utils.py", line 51, in single_nb_execution
    executenb(
  File "/Users/pytka/opt/anaconda3/lib/python3.8/site-packages/nbclient/client.py", line 1087, in execute
    return NotebookClient(nb=nb, resources=resources, km=km, **kwargs).execute()
  File "/Users/pytka/opt/anaconda3/lib/python3.8/site-packages/nbclient/util.py", line 74, in wrapped
    return just_run(coro(*args, **kwargs))
  File "/Users/pytka/opt/anaconda3/lib/python3.8/site-packages/nbclient/util.py", line 53, in just_run
    return loop.run_until_complete(coro)
  File "/Users/pytka/opt/anaconda3/lib/python3.8/asyncio/base_events.py", line 616, in run_until_complete
    return future.result()
  File "/Users/pytka/opt/anaconda3/lib/python3.8/site-packages/nbclient/client.py", line 540, in async_execute
    await self.async_execute_cell(
  File "/Users/pytka/opt/anaconda3/lib/python3.8/site-packages/nbclient/client.py", line 832, in async_execute_cell
    self._check_raise_for_error(cell, exec_reply)
  File "/Users/pytka/opt/anaconda3/lib/python3.8/site-packages/nbclient/client.py", line 740, in _check_raise_for_error
    raise CellExecutionError.from_cell_and_msg(cell, exec_reply['content'])
nbclient.exceptions.CellExecutionError: An error occurred while executing the following cell:
------------------
Int8(2^8) #Error message
------------------

InexactError: trunc(Int8, 256)

Stacktrace:
 [1] throw_inexacterror(f::Symbol, #unused#::Type{Int8}, val::Int64)
   @ Core ./boot.jl:602
 [2] checked_trunc_sint
   @ ./boot.jl:624 [inlined]
 [3] toInt8
   @ ./boot.jl:639 [inlined]
 [4] Int8(x::Int64)
   @ Core ./boot.jl:749
 [5] top-level scope
   @ In[5]:1
 [6] eval
   @ ./boot.jl:360 [inlined]
 [7] include_string(mapexpr::typeof(REPL.softscope), mod::Module, code::String, filename::String)
   @ Base ./loading.jl:1094
LoadError: InexactError: trunc(Int8, 256)

